cp: `../../data/dataset/*.gbff' を stat できません: そのようなファイルやディレクトリはありません
Traceback (most recent call last):
  File "../../scripts/gbk2fna.py", line 6, in <module>
    SeqIO.convert(filename, "genbank", filename+".fna", "fasta")
  File "/home/t16965tw/miniconda3/envs/bio/lib/python3.6/site-packages/Bio/SeqIO/__init__.py", line 1091, in convert
    with as_handle(in_file, in_mode) as in_handle:
  File "/home/t16965tw/miniconda3/envs/bio/lib/python3.6/contextlib.py", line 81, in __enter__
    return next(self.gen)
  File "/home/t16965tw/miniconda3/envs/bio/lib/python3.6/site-packages/Bio/File.py", line 118, in as_handle
    with open(handleish, mode, **kwargs) as fp:
FileNotFoundError: [Errno 2] No such file or directory: './data/*.gbff'
mv: `data/*.fasta' を stat できません: そのようなファイルやディレクトリはありません
/var/spool/pbs/mom_priv/jobs/3603366.bias5-adm.SC: 行 16: ./data/./data/*.gbff.faa: そのようなファイルやディレクトリはありません
